Workbook

Sheet Read me
A1: Case 4 - value at risk
A3: What this is
A4: A value-at-risk model for the three leaks in Case 4, built so that every number can be traced to where it came from.
A6: How to use it
A7: Change any value in column C of the Assumptions sheet, or a low or high in columns D and E. Every other sheet is formulas, so the answer moves with it. No input is typed into a formula anywhere in this workbook; the only literals are unit conversions, the halving of a two-sided spread, the floor at zero on leak 3's expected level and curve line, and the month arithmetic on the upgrade-timing sheet.
A9: The five tiers
A10: MEASURED (456 inputs) - our own analysis of 3.9 million used-car listings from 29 sources. The source column names the report and `check_assumptions.py` re-reads the figure out of it.
A11: SOURCED (354 inputs) - published figures with a URL: Stellantis's FY2025 results and Form 20-F, Eurostat and ONS price indices, published studies.
A12: ASSUMPTION (29 inputs) - our judgement, each with a low and a high and a caveat saying what it rests on. These are the rows a pilot should replace with evidence.
A13: TARGET (31 inputs) - a level the team chose rather than found: a phase gate or a KPI threshold. These are commitments, not findings, so `check_assumptions.py` refuses to let one feed a value-at-risk formula, and the audit keeps every one out of every formula.
A14: SYNTHETIC (50 inputs) - results of the leak-1 test harness, a world we or a blind red team built, and of the ledger prototype built on it. They measure the tool, not the group, so they are quoted only as rankings, failures and engineering facts, and both checkers refuse to let one feed a formula.
A16: Which of them move the answer
... A36: .venv/bin/python build_var_model.py # rebuilds this workbook

Sheet Assumptions
A1: id | B1: label | C1: value | D1: low | E1: high | F1: unit | G1: tier | H1: source | I1: url | J1: as of | K1: caveat | L1: used in
A2: eu_shipments | B2: Enlarged Europe consolidated shipments | C2: 2490000 | F2: units | G2: SOURCED | H2: Stellantis FY2025 results press release (SEC-filed) | I2: https://www.sec.gov/Archives/edgar/data/1605484/000160548426000019/stellantisnvfy2025pressrel.htm | J2: FY2025 | K2: Down from 2,576k in FY2024. Enlarged Europe is the EU-27, the UK and EFTA (plus Israel and Palestine from 2025); Middle East & Africa is a separate segment. | L2: Leak 1;Leak 2
A3: eu_revenue_eur_m | B3: Enlarged Europe net revenues | C3: 57773 | F3: EUR m | G3: SOURCED | H3: Stellantis FY2025 results press release (SEC-filed) | I3: https://www.sec.gov/Archives/edgar/data/1605484/000160548426000019/stellantisnvfy2025pressrel.htm | J3: FY2025 | K3: Segment revenue; not only new-vehicle sales. | L3: Leak 1
A4: eu_aoi_eur_m | B4: Enlarged Europe adjusted operating income | C4: -651 | F4: EUR m | G4: SOURCED | H4: Stellantis FY2025 results press release (SEC-filed) | I4: https://www.sec.gov/Archives/edgar/data/1605484/000160548426000019/stellantisnvfy2025pressrel.htm | J4: FY2025 | K4: A swing of -3,070m from +2,419m in FY2024. Context for urgency; not an input to the VaR. | L4: Context
A5: group_shipments | B5: Group consolidated shipments | C5: 5484000 | F5: units | G5: SOURCED | H5: Stellantis FY2025 results press release (SEC-filed) | I5: https://www.sec.gov/Archives/edgar/data/1605484/000160548426000019/stellantisnvfy2025pressrel.htm | J5: FY2025 | L5: Context
A6: group_revenue_eur_m | B6: Group net revenues | C6: 153508 | F6: EUR m | G6: SOURCED | H6: Stellantis FY2025 results press release (SEC-filed) | I6: https://www.sec.gov/Archives/edgar/data/1605484/000160548426000019/stellantisnvfy2025pressrel.htm | J6: FY2025 | L6: Context
A7: buyback_payables_eur_m | B7: Payables for buy-back agreements | C7: 7889 | F7: EUR m | G7: SOURCED | H7: Stellantis Form 20-F FY2025 Note 24 Other liabilities | I7: https://www.sec.gov/Archives/edgar/data/1605484/000160548426000021/stellantis-20251231.htm | J7: 2025-12-31 | K7: Current 5313 + non-current 2576. The residual exposure base. Note 24 defines it as the price received, recognised as an advance at sale, and subsequently the repurchase price and the remaining lease installments yet to be recognized: so it is the repurchase price plus lease income not yet recognised, an upper bound on the repurchase amount (close to it near maturity, which is the current part) (X18). | L7: Leak 3
A8: buyback_payables_current_eur_m | B8: Payables for buy-back agreements due within one year | C8: 5313 | F8: EUR m | G8: SOURCED | H8: Stellantis Form 20-F FY2025 Note 24 Other liabilities, current column | I8: https://www.sec.gov/Archives/edgar/data/1605484/000160548426000021/stellantis-20251231.htm | J8: 2025-12-31 | K8: The part of the 7,889m that comes back within twelve months, so the base of a per-year figure. The 2,576m due after one year is counted in the year it falls due. | L8: Leak 3
A9: buyback_term_policy | B9: Contracts of 12 months or less are booked as assets sold with a buy-back commitment | F9: text | G9: SOURCED | H9: Stellantis Form 20-F FY2025, revenue recognition: "recorded within Assets sold with a buy-back commitment if the contract term is 12 months or less, and recorded in Property, plant and equipment if the contract term is greater than 12 months" | I9: https://www.sec.gov/Archives/edgar/data/1605484/000160548426000021/stellantis-20251231.htm | J9: FY2025 | K9: Why most of the book is short-dated. | L9: Context
A10: buyback_value_decrease_2025_eur_m | B10: Decrease in value booked on assets sold with a buy-back commitment - 2025 | C10: 358 | F10: EUR m | G10: SOURCED | H10: Stellantis Form 20-F FY2025, cost of revenues: "EUR 358 million, EUR 179 million and EUR 82 million related to the decrease in value for assets sold with buy-back commitments" (2025, 2024, 2023) | I10: https://www.sec.gov/Archives/edgar/data/1605484/000160548426000021/stellantis-20251231.htm | J10: FY2025 | K10: Scheduled depreciation, not a loss: the 20-F FY2025 policy says 'the difference between the cost of the vehicle and the estimated net residual value is recognized within Cost of revenues ... over the contractual term'. Contracts of 12 months or less. As a share of year-end buy-back assets it is about a year's ordinary depreciation (X6 part 4), so it cannot check leak 3. The group discloses no gains or losses at disposal for this book. | L10: Context
A11: buyback_value_decrease_2024_eur_m | B11: Decrease in value booked on assets sold with a buy-back commitment - 2024 | C11: 179 | F11: EUR m | G11: SOURCED | H11: Stellantis Form 20-F FY2025, cost of revenues (same sentence) | I11: https://www.sec.gov/Archives/edgar/data/1605484/000160548426000021/stellantis-20251231.htm | J11: FY2024 | K11: See buyback_value_decrease_2025_eur_m. | L11: Context
A12: buyback_value_decrease_2023_eur_m | B12: Decrease in value booked on assets sold with a buy-back commitment - 2023 | C12: 82 | F12: EUR m | G12: SOURCED | H12: Stellantis Form 20-F FY2025, cost of revenues (same sentence) | I12: https://www.sec.gov/Archives/edgar/data/1605484/000160548426000021/stellantis-20251231.htm | J12: FY2023 | K12: See buyback_value_decrease_2025_eur_m. | L12: Context
A13: buyback_assets_eur_m | B13: Assets sold with a buy-back commitment | C13: 3616 | F13: EUR m | G13: SOURCED | H13: Stellantis Form 20-F FY2025 consolidated balance sheet | I13: https://www.sec.gov/Archives/edgar/data/1605484/000160548426000021/stellantis-20251231.htm | J13: 2025-12-31 | K13: Asset side of the same arrangements; 1938m in 2024. Shown for scale only to avoid double counting. | L13: Context
A14: rv_review_months | B14: Frequency of residual-value review today | C14: 3 | F14: months | G14: SOURCED | H14: Stellantis Form 20-F FY2025: "Expected residual values are analyzed quarterly and depreciation rates are adjusted accordingly" | I14: https://www.sec.gov/Archives/edgar/data/1605484/000160548426000021/stellantis-20251231.htm | J14: FY2025 | K14: The group's stated practice. Our recommendation is monthly. | L14: Leak 3
A15: rv_method_today | B15: Residual values use third-party estimates plus in-house modelling | F15: text | G15: SOURCED | H15: Stellantis Form 20-F FY2025: "Third party estimates are utilized in conjunction with proprietary modelling" | I15: https://www.sec.gov/Archives/edgar/data/1605484/000160548426000021/stellantis-20251231.htm | J15: FY2025 | K15: Answers the build-vs-buy question: they already buy; the gap is their own discount and launch plans. | L15: Context
A16: lev_residual_uncertainty | B16: Electrified residuals are harder because resale history is thin | F16: text | G16: SOURCED | H16: Stellantis Form 20-F FY2025: "Residual values for LEVs are subject to greater uncertainty than for ICE vehicles, due to limited historical resale data" | I16: https://www.sec.gov/Archives/edgar/data/1605484/000160548426000021/stellantis-20251231.htm | J16: FY2025 | K16: The group's own words for the little-history problem our pooling result addresses. | L16: Leak 3
A17: schloter_ev_dep_month | B17: Depreciation of used electric cars a month (Schloter 2022) | C17: 1.16 | F17: % a month | G17: SOURCED | H17: Schloter, Empirical analysis of the depreciation of electric vehicles compared to gasoline vehicles, Transport Policy 126 (2022) 268-279, abstract (TRID record) | I17: https://trid.trb.org/View/2005004 | J17: 2022 | K17: 24,000 used-vehicle sales across several countries and segments, web data of 2020-21 (not Norway, as the user's research report said). A benchmark for ev_level_report.md's curve, not an input. | L17: Context: X9 (EV residual risk)
A18: schloter_petrol_dep_month | B18: Depreciation of used petrol cars a month (Schloter 2022) | C18: 0.87 | F18: % a month | G18: SOURCED | H18: Schloter, Empirical analysis of the depreciation of electric vehicles compared to gasoline vehicles, Transport Policy 126 (2022) 268-279, abstract (TRID record) | I18: https://trid.trb.org/View/2005004 | J18: 2022 | K18: As schloter_ev_dep_month. | L18: Context: X9 (EV residual risk)
A19: fitch_eu_abs_bev_share_q3_2024 | B19: BEV share of Fitch-rated European loan and lease ABS, Q3 2024 | C19: 11 | F19: % | G19: SOURCED | H19: Fitch Ratings, Higher BEV Exposures Increase RV Risk in European Auto Lease ABS (27 January 2025), as reported by Motor Finance Online, 12 February 2025 | I19: https://www.motorfinanceonline.com/news/bev-exposure-in-european-auto-lease-abs-raises-residual-value-risk-fitch/ | J19: 2024-09-30 | K19: 'Close to 11%'; about 6% in 2023. Secondary source: Fitch's page refuses automated reading. Fitch: 'Since 2023, used BEV prices have fallen more sharply than those of other powertrains'; one Dutch lease portfolio is nearly 50% BEV. | L19: Context: X9 (EV residual risk)
A20: euro7_battery_mpr_m1_5y | B20: Euro 7 minimum battery energy for M1 cars (BEV and PHEV), start of life to 5 years or 100,000 km | C20: 80 | F20: % of certified energy | G20: SOURCED | H20: Regulation (EU) 2024/1257 (Euro 7), Annex II Table 1 | I20: https://eur-lex.europa.eu/legal-content/EN/TXT/HTML/?uri=CELEX:32024R1257 | J20: 2024-04-24 | K20: A type-approval requirement checked on the vehicle type in service, not a per-car warranty; applies to new M1 types from 29 November 2026 and all new M1 cars from 29 November 2027 (Article 21). N1 vans: 75% (Table 2). | L20: Context: X9 (EV residual risk)
A21: euro7_battery_mpr_m1_8y | B21: The same, more than 5 years or 100,000 km and up to 8 years or 160,000 km | C21: 72 | F21: % of certified energy | G21: SOURCED | H21: Regulation (EU) 2024/1257 (Euro 7), Annex II Table 1 | I21: https://eur-lex.europa.eu/legal-content/EN/TXT/HTML/?uri=CELEX:32024R1257 | J21: 2024-04-24 | K21: As euro7_battery_mpr_m1_5y. N1 vans: 67% (Table 2). Battery durability data readable through the OBD port. | L21: Context: X9 (EV residual risk)
A22: battreg_soh_access_from | B22: EV battery state of health held in the battery management system, readable by the battery's legal purchaser for evaluating its residual value, from 18 August 2024 | C22: 2024.63 | F22: year | G22: SOURCED | H22: Regulation (EU) 2023/1542 (Batteries), Article 14(1)-(2) and Annex VII Part A (state of certified energy) | I22: https://eur-lex.europa.eu/legal-content/EN/TXT/HTML/?uri=CELEX:32023R1542 | J22: 2023-07-12 | K22: 18 August 2024 as a decimal year. Read-only access, respecting the battery maker's intellectual property, for the legal purchaser or a party acting for them; purpose (b) is 'evaluating the residual value'. A captive that owns its leased EVs may read each one's state of health at return. | L22: Context: X9 (EV residual risk)
A23: battreg_passport_from | B23: Battery passport required for every EV battery placed on the market, from 18 February 2027 | C23: 2027.13 | F23: year | G23: SOURCED | H23: Regulation (EU) 2023/1542 (Batteries), Article 77(1) | I23: https://eur-lex.europa.eu/legal-content/EN/TXT/HTML/?uri=CELEX:32023R1542 | J23: 2023-07-12 | K23: 18 February 2027 as a decimal year. The passport carries model and individual-battery information (Annex XIII), part public, part for persons with a legitimate interest. | L23: Context: X9 (EV residual risk)
A24: geotab_degradation_pct_year | B24: Average EV battery capacity loss a year (Geotab) | C24: 2.3 | F24: % a year | G24: SOURCED | H24: Geotab, What can 10,000+ EVs tell us about battery health? (22,700+ vehicles; 1.5% with little DC fast charging, 3.0% with frequent fast charging) | I24: https://www.geotab.com/blog/ev-battery-health/ | J24: 2024 | K24: Telematics fleet data; Geotab does not say what share is European. Checked by a research agent on 24 September. | L24: Context: X9 (EV residual risk)
A25: incentive_not_disclosed | B25: Total sales incentive spend is not disclosed | F25: text | G25: SOURCED | H25: Stellantis Form 20-F FY2025: sales incentives are a critical estimate; "estimated incentive rates are reviewed monthly" | I25: https://www.sec.gov/Archives/edgar/data/1605484/000160548426000021/stellantis-20251231.htm | J25: FY2025 | K25: This is why every Leak 1 figure below is an assumption rather than a sourced number. X14 (26 September): no regional total is disclosed, but Note 21's sales-incentive provision and its roll-forward are, worldwide (sales_incentive_*); leak 1's claims line now rests on them. | L25: Leak 1
A26: ons_uk_index_move | B26: UK second-hand car index move 2018-01 to 2022-10 | C26: 26.6 | F26: % | G26: SOURCED | H26: ONS CPI 07.1.1B second-hand cars (series D7E9) via data/reference/price_indices.parquet | I26: https://www.ons.gov.uk/economy/inflationandpriceindices | J26: 2022-10 | K26: Independent measure of the UK level move behind the Corsa example. | L26: Leak 3
A27: dealer_passthrough_low | B27: Share of a dealer discount that reaches the buyer | C27: 30 | D27: 30 | E27: 40 | F27: % | G27: SOURCED | H27: Busse, Silva-Risso & Zettelmeyer, $1,000 Cash Back, American Economic Review 2006 | I27: https://www.aeaweb.org/articles?id=10.1257/aer.96.4.1253 | J27: 2006 | K27: US data. Customer rebates pass through at 70-90%; dealer discounts at 30-40%. | L27: Leak 1
A28: dep_pooled | B28: Depreciation per year of age | C28: -9.2 | D28: -10 | E28: -7.9 | F28: % | G28: MEASURED | H28: analysis/drivers_report.md pooled effects table | J28: 2026-09-17 | K28: 16 datasets, 2,617,260 cars. Random-effects pooled; the single pooled model says -10.7%. Age alone, with mileage held fixed: a lease-age car also being driven loses about 12% a year (drivers_report.md). | L28: Leak 2;Leak 3
A29: dep_with_mileage_3y | B29: Yearly value loss at 3 years old, age plus a typical year's mileage | C29: -12 | F29: % | G29: MEASURED | H29: analysis/drivers_report.md | J29: 2026-09-17 | K29: Pooled age effect plus the pooled mileage effect for the extra mileage a steadily driven car adds between 3 and 4 years old. | L29: Context
A30: dep_market_min | B30: Fastest depreciation of any market measured | C30: -13.3 | F30: % | G30: MEASURED | H30: analysis/drivers_report.md per-dataset spread (dvm) | J30: 2026-09-17 | K30: The rate is real everywhere but its size is local. | L30: Leak 3
A31: dep_market_max | B31: Slowest depreciation of any market measured | C31: -4.9 | F31: % | G31: MEASURED | H31: analysis/drivers_report.md per-dataset spread (eg_hatla2ee) | J31: 2026-09-17 | K31: Egypt; a market unlike the group's European ones. | L31: Leak 3
A32: dep_uk | B32: UK depreciation per year of age | C32: -10.4 | F32: % | G32: MEASURED | H32: analysis/drivers_report.md per-dataset (uk_2022_10) | J32: 2026-09-17 | K32: Advert prices. | L32: Leak 2
A33: dep_stability_lo | B33: Slowest monthly estimate of the rate over 52 months | C33: -13.2 | F33: % | G33: MEASURED | H33: analysis/latvia_time_report.md | J33: 2026-09-17 | K33: Latvia, one market. The rate never left this band through the 2021-22 shortage. | L33: Leak 3
A34: dep_stability_hi | B34: Fastest monthly estimate of the rate over 52 months | C34: -11.7 | F34: % | G34: MEASURED | H34: analysis/latvia_time_report.md | J34: 2026-09-17 | K34: Latvia, one market. Standard deviation 0.38 points. | L34: Leak 3
A35: latvia_index_corr | B35: Correlation of our Latvian price index with Eurostat's | C35: 0.958 | F35: r | G35: MEASURED | H35: analysis/latvia_time_report.md | J35: 2026-09-17 | K35: Correlation of index levels, which two rising series share whatever they measure. As changes: 12-month moves agree (0.90), month-on-month moves do not (-0.03). Disagrees on size (+42% vs +8.8%). | L35: Context
A36: retained_3y_pooled | B36: Value retained at 3 years at the pooled rate | C36: 75 | F36: % of list | G36: MEASURED | H36: analysis/level_risk_report.md (derived from dep_pooled) | J36: 2026-09-17 | K36: Arithmetic on the pooled rate; the denominator for turning points of list price into a share of residual value. | L36: Leak 3
A37: retained_3y_uk | B37: Value retained at 3 years - UK (2018 adverts) | C37: 66 | F37: % of list | G37: MEASURED | H37: analysis/value_retained_report.md | J37: 2026-09-17 | K37: DVM adverts, mostly 2018, before the shortage. The UK's October 2022 scrape gives 90% (retained_3y_uk_2022); pooling the two blends eras. Entry-trim new price flatters the share. | L37: Leak 2
A38: retained_3y_uk_2022 | B38: Value retained at 3 years - UK (October 2022 adverts) | C38: 90 | F38: % of list | G38: MEASURED | H38: analysis/value_retained_report.md | J38: 2026-09-17 | K38: Shortage peak, and a different scrape from the 2018 row, so the +24-point gap mixes a market move with a source difference. | L38: Context
A39: retained_3y_nl | B39: Value retained at 3 years - Netherlands | C39: 60 | F39: % of list | G39: MEASURED | H39: analysis/value_retained_report.md | J39: 2026-09-25 | K39: Deflated by BPM registration tax in the list price. Not comparable in level with the others. | L39: Context
A40: retained_3y_us | B40: Value retained at 3 years - US | C40: 68 | F40: % of list | G40: MEASURED | H40: analysis/value_retained_report.md | J40: 2026-09-17 | K40: US data. Sample of 690 cars. | L40: Context
...

Sheet Summary
A1: Value at risk - summary
A2: EUR millions a year, in two measures (X18): expected a year, what to budget, and in a one-in-ten-year market, what a bad year costs. They sit side by side and are never added. Every cell is a formula over the Assumptions sheet; change an input there and this moves.
B4: expected a year | C4: in a one-in-ten-year market | F4: what drives it
A5: Leak 1 - incentives paid wrongly or needlessly | B5: =(eu_revenue_eur_m * x14_incentive_claims_central/100 * process_leak_pct/100 + eu_revenue_eur_m * x5_targeting_gain_central/100) -> 142.06381 | C5: =(eu_revenue_eur_m * x14_incentive_claims_central/100 * process_leak_pct/100 + eu_revenue_eur_m * x5_targeting_gain_central/100) -> 142.06381 | F5: claims base disclosed (worldwide), leak rate assumed; targeting derived from published studies
A6: Leak 2 - upgrade moments missed | B6: =sfse_eu_nv_contracts_2025 * upgrade_capture_uplift/100 * margin_per_repeat_sale / 1000000 -> 38.76828 | C6: =sfse_eu_nv_contracts_2025 * upgrade_capture_uplift/100 * margin_per_repeat_sale / 1000000 -> 38.76828 | F6: timing is measured, the euro conversion is assumed
A7: Leak 3 - residual value | B7: =(buyback_payables_current_eur_m * MAX(0, x18_exp_twosided_book)/100 + buyback_payables_current_eur_m * (x17_days_cut * x17_day_cost_central/10000 + x17_share_routed/100 * x17_channel_gain_after_costs/100)) -> 24.81171 | C7: =((buyback_payables_current_eur_m * (ABS(level_1y_p10_book)/100 + (curve_1y_p80_known/2/retained_1y_pooled * (1 - thin_share_of_book/100) + curve_1y_p80_unknown/2/retained_1y_pooled * thin_share_of_book/100))) * x18_joint_share_book/100 + buyback_payables_current_eur_m * (x17_days_cut * x17_day_cost_central/10000 + x17_share_routed/100 * x17_channel_gain_after_costs/100)) -> 117.28313 | F7: book due within a year disclosed. Expected: the level and curve count both ways and gained on the book's record, so zero, plus resale execution. One in ten: their joint p10, measured, plus execution
A8: Total value at risk a year | B8: =(eu_revenue_eur_m * x14_incentive_claims_central/100 * process_leak_pct/100 + eu_revenue_eur_m * x5_targeting_gain_central/100) + sfse_eu_nv_contracts_2025 * upgrade_capture_uplift/100 * margin_per_repeat_sale / 1000000 + (buyback_payables_current_eur_m * MAX(0, x18_exp_twosided_book)/100 + buyback_payables_current_eur_m * (x17_days_cut * x17_day_cost_central/10000 + x17_share_routed/100 * x17_channel_gain_after_costs/100)) -> 205.6438 | C8: =(eu_revenue_eur_m * x14_incentive_claims_central/100 * process_leak_pct/100 + eu_revenue_eur_m * x5_targeting_gain_central/100) + sfse_eu_nv_contracts_2025 * upgrade_capture_uplift/100 * margin_per_repeat_sale / 1000000 + ((buyback_payables_current_eur_m * (ABS(level_1y_p10_book)/100 + (curve_1y_p80_known/2/retained_1y_pooled * (1 - thin_share_of_book/100) + curve_1y_p80_unknown/2/retained_1y_pooled * thin_share_of_book/100))) * x18_joint_share_book/100 + buyback_payables_current_eur_m * (x17_days_cut * x17_day_cost_central/10000 + x17_share_routed/100 * x17_channel_gain_after_costs/100)) -> 298.11522 | F8: the two columns answer different questions; never add or average them
A9: Upper end, in no total | B9: =(eu_revenue_eur_m * x14_incentive_claims_central/100 * process_leak_pct/100 + eu_revenue_eur_m * x5_targeting_gain_central/100) + sfse_eu_nv_contracts_2025 * upgrade_capture_uplift/100 * margin_per_repeat_sale / 1000000 + (buyback_payables_current_eur_m * MAX(0, x18_exp_twosided_book)/100 + buyback_payables_current_eur_m * (x17_days_cut * x17_day_cost_central/10000 + x17_share_routed/100 * x17_channel_gain_after_costs/100)) + buyback_payables_current_eur_m * x18_exp_onesided_book/100 -> 266.69017 | C9: =(eu_revenue_eur_m * x14_incentive_claims_central/100 * process_leak_pct/100 + eu_revenue_eur_m * x5_targeting_gain_central/100) + sfse_eu_nv_contracts_2025 * upgrade_capture_uplift/100 * margin_per_repeat_sale / 1000000 + (buyback_payables_current_eur_m * (ABS(level_1y_p10_book)/100 + (curve_1y_p80_known/2/retained_1y_pooled * (1 - thin_share_of_book/100) + curve_1y_p80_unknown/2/retained_1y_pooled * thin_share_of_book/100)) + buyback_payables_current_eur_m * (x17_days_cut * x17_day_cost_central/10000 + x17_share_routed/100 * x17_channel_gain_after_costs/100)) -> 339.85486 | F9: expected: as if every buy-back were a customer's put at the residual; one in ten: the level and the curve at their p10s at once
A10: Stress: the whole book in a core market's bad year (-4.5%) | C10: =(eu_revenue_eur_m * x14_incentive_claims_central/100 * process_leak_pct/100 + eu_revenue_eur_m * x5_targeting_gain_central/100) + sfse_eu_nv_contracts_2025 * upgrade_capture_uplift/100 * margin_per_repeat_sale / 1000000 + ((buyback_payables_current_eur_m * (ABS(level_1y_p10_core)/100 + (curve_1y_p80_known/2/retained_1y_pooled * (1 - thin_share_of_book/100) + curve_1y_p80_unknown/2/retained_1y_pooled * thin_share_of_book/100))) * x18_joint_share_stress/100 + buyback_payables_current_eur_m * (x17_days_cut * x17_day_cost_central/10000 + x17_share_routed/100 * x17_channel_gain_after_costs/100)) -> 455.94236 | F10: a Europe-wide bad year as deep as a core market's one-in-ten; the book's short history lacks one
A11: Stress, upper end, in no total | C11: =(eu_revenue_eur_m * x14_incentive_claims_central/100 * process_leak_pct/100 + eu_revenue_eur_m * x5_targeting_gain_central/100) + sfse_eu_nv_contracts_2025 * upgrade_capture_uplift/100 * margin_per_repeat_sale / 1000000 + (buyback_payables_current_eur_m * (ABS(level_1y_p10_core)/100 + (curve_1y_p80_known/2/retained_1y_pooled * (1 - thin_share_of_book/100) + curve_1y_p80_unknown/2/retained_1y_pooled * thin_share_of_book/100)) + buyback_payables_current_eur_m * (x17_days_cut * x17_day_cost_central/10000 + x17_share_routed/100 * x17_channel_gain_after_costs/100)) -> 503.97343 | F11: the same with the level and the curve at their p10s at once
A12: Total without the targeting line | B12: =(eu_revenue_eur_m * x14_incentive_claims_central/100 * process_leak_pct/100 + eu_revenue_eur_m * x5_targeting_gain_central/100) + sfse_eu_nv_contracts_2025 * upgrade_capture_uplift/100 * margin_per_repeat_sale / 1000000 + (buyback_payables_current_eur_m * MAX(0, x18_exp_twosided_book)/100 + buyback_payables_current_eur_m * (x17_days_cut * x17_day_cost_central/10000 + x17_share_routed/100 * x17_channel_gain_after_costs/100)) - eu_revenue_eur_m * x5_targeting_gain_central/100 -> 141.57354 | C12: =(eu_revenue_eur_m * x14_incentive_claims_central/100 * process_leak_pct/100 + eu_revenue_eur_m * x5_targeting_gain_central/100) + sfse_eu_nv_contracts_2025 * upgrade_capture_uplift/100 * margin_per_repeat_sale / 1000000 + ((buyback_payables_current_eur_m * (ABS(level_1y_p10_book)/100 + (curve_1y_p80_known/2/retained_1y_pooled * (1 - thin_share_of_book/100) + curve_1y_p80_unknown/2/retained_1y_pooled * thin_share_of_book/100))) * x18_joint_share_book/100 + buyback_payables_current_eur_m * (x17_days_cut * x17_day_cost_central/10000 + x17_share_routed/100 * x17_channel_gain_after_costs/100)) - eu_revenue_eur_m * x5_targeting_gain_central/100 -> 234.04496 | F12: paying buyers who would buy anyway is the cost of any incentive
A14: What the programme gets back (the Benefits sheet, X21)
A15: Addressable: what the levers can reach, every source | B15: =eu_revenue_eur_m * x14_incentive_claims_central/100 * process_leak_pct/100 + eu_revenue_eur_m * x5_targeting_gain_central/100 * finance_penetration/100 + sfse_eu_nv_contracts_2025 * upgrade_capture_uplift/100 * margin_per_repeat_sale / 1000000 + buyback_payables_current_eur_m * (x17_days_cut * x17_day_cost_central/10000 + x17_share_routed/100 * x17_channel_gain_after_costs/100) + buyback_payables_current_eur_m * MAX(0, x18_exp_twosided_book)/100 -> 160.08984 | C15: - | F15: reach, not benefit (the Data reach sheet, X20)
A16: Planned benefit, committed levers | B16: =(eu_revenue_eur_m * x14_incentive_claims_central/100 * process_leak_pct/100 * recoverable_share/100) + (sfse_eu_nv_contracts_2025 * upgrade_capture_uplift/100 * margin_per_repeat_sale / 1000000) + (buyback_payables_current_eur_m * x17_days_cut * x17_day_cost_central/10000) + (buyback_payables_current_eur_m * x17_share_routed/100 * x17_channel_gain_after_costs/100) -> 86.978055 | C16: =(eu_revenue_eur_m * x14_incentive_claims_central/100 * process_leak_pct/100 * recoverable_share/100) + (sfse_eu_nv_contracts_2025 * upgrade_capture_uplift/100 * margin_per_repeat_sale / 1000000) + (buyback_payables_current_eur_m * x17_days_cut * x17_day_cost_central/10000) + (buyback_payables_current_eur_m * x17_share_routed/100 * x17_channel_gain_after_costs/100) + buyback_payables_current_eur_m * thin_share_of_book/100 * (curve_1y_p80_unknown - curve_1y_p80_known)/2/retained_1y_pooled * x18_joint_share_book/100 -> 107.6398 | F16: claims controls, retention, resale execution; one year in ten adds the little-history cut
A17: The same at the reference class | B17: =(1-mckox_sw_benefit_shortfall_pct/100) * ((eu_revenue_eur_m * x14_incentive_claims_central/100 * process_leak_pct/100 * recoverable_share/100) + (sfse_eu_nv_contracts_2025 * upgrade_capture_uplift/100 * margin_per_repeat_sale / 1000000) + (buyback_payables_current_eur_m * x17_days_cut * x17_day_cost_central/10000) + (buyback_payables_current_eur_m * x17_share_routed/100 * x17_channel_gain_after_costs/100)) -> 72.191786 | C17: =(1-mckox_sw_benefit_shortfall_pct/100) * ((eu_revenue_eur_m * x14_incentive_claims_central/100 * process_leak_pct/100 * recoverable_share/100) + (sfse_eu_nv_contracts_2025 * upgrade_capture_uplift/100 * margin_per_repeat_sale / 1000000) + (buyback_payables_current_eur_m * x17_days_cut * x17_day_cost_central/10000) + (buyback_payables_current_eur_m * x17_share_routed/100 * x17_channel_gain_after_costs/100) + buyback_payables_current_eur_m * thin_share_of_book/100 * (curve_1y_p80_unknown - curve_1y_p80_known)/2/retained_1y_pooled * x18_joint_share_book/100) -> 89.341036 | F17: large software projects fall short of their benefits on average (McKinsey-Oxford)
A18: Certified today | B18: 0 | C18: 0 | F18: every committed rate is an assumption; Finance certifies from Phase 1
A21: Range from the assumed inputs
B22: low | C22: base | D22: high
A23: Leak 1 | B23: =(eu_revenue_eur_m * x14_incentive_claims_low/100 * Assumptions!$D$114/100 + eu_revenue_eur_m * x5_targeting_gain_low/100) -> 48.818185 | C23: =(eu_revenue_eur_m * x14_incentive_claims_central/100 * process_leak_pct/100 + eu_revenue_eur_m * x5_targeting_gain_central/100) -> 142.06381 | D23: =(eu_revenue_eur_m * x14_incentive_claims_high/100 * Assumptions!$E$114/100 + eu_revenue_eur_m * x5_targeting_gain_high/100) -> 325.08867
A24: Leak 2 | B24: =sfse_eu_nv_contracts_2025 * Assumptions!$D$134/100 * Assumptions!$D$135 / 1000000 -> 6.46138 | C24: =sfse_eu_nv_contracts_2025 * upgrade_capture_uplift/100 * margin_per_repeat_sale / 1000000 -> 38.76828 | D24: =sfse_eu_nv_contracts_2025 * Assumptions!$E$134/100 * Assumptions!$E$135 / 1000000 -> 135.68898
A25: Leak 3, expected a year | B25: =(buyback_payables_current_eur_m * MAX(0, x18_exp_twosided_book)/100 + buyback_payables_current_eur_m * (Assumptions!$D$685 * x17_day_cost_low/10000 + Assumptions!$D$686/100 * x17_channel_gain_after_costs/100)) -> 10.99791 | C25: =(buyback_payables_current_eur_m * MAX(0, x18_exp_twosided_book)/100 + buyback_payables_current_eur_m * (x17_days_cut * x17_day_cost_central/10000 + x17_share_routed/100 * x17_channel_gain_after_costs/100)) -> 24.81171 | D25: =(buyback_payables_current_eur_m * MAX(0, x18_exp_twosided_book)/100 + buyback_payables_current_eur_m * (Assumptions!$E$685 * x17_day_cost_high/10000 + Assumptions!$E$686/100 * x17_channel_gain_before_opex/100)) -> 125.81184
A26: Leak 3, one year in ten | B26: =((buyback_payables_current_eur_m * (ABS(level_1y_p10_book)/100 + (curve_1y_p80_known/2/retained_1y_pooled * (1 - Assumptions!$D$117/100) + curve_1y_p80_unknown/2/retained_1y_pooled * Assumptions!$D$117/100))) * x18_joint_share_book/100 + buyback_payables_current_eur_m * (Assumptions!$D$685 * x17_day_cost_low/10000 + Assumptions!$D$686/100 * x17_channel_gain_after_costs/100)) -> 91.072282 | C26: =((buyback_payables_current_eur_m * (ABS(level_1y_p10_book)/100 + (curve_1y_p80_known/2/retained_1y_pooled * (1 - thin_share_of_book/100) + curve_1y_p80_unknown/2/retained_1y_pooled * thin_share_of_book/100))) * x18_joint_share_book/100 + buyback_payables_current_eur_m * (x17_days_cut * x17_day_cost_central/10000 + x17_share_routed/100 * x17_channel_gain_after_costs/100)) -> 117.28313 | D26: =((buyback_payables_current_eur_m * (ABS(level_1y_p10_book)/100 + (curve_1y_p80_known/2/retained_1y_pooled * (1 - Assumptions!$E$117/100) + curve_1y_p80_unknown/2/retained_1y_pooled * Assumptions!$E$117/100))) * x18_joint_share_book/100 + buyback_payables_current_eur_m * (Assumptions!$E$685 * x17_day_cost_high/10000 + Assumptions!$E$686/100 * x17_channel_gain_before_opex/100)) -> 230.68031
A27: Total, expected a year | B27: =(eu_revenue_eur_m * x14_incentive_claims_low/100 * Assumptions!$D$114/100 + eu_revenue_eur_m * x5_targeting_gain_low/100) + sfse_eu_nv_contracts_2025 * Assumptions!$D$134/100 * Assumptions!$D$135 / 1000000 + (buyback_payables_current_eur_m * MAX(0, x18_exp_twosided_book)/100 + buyback_payables_current_eur_m * (Assumptions!$D$685 * x17_day_cost_low/10000 + Assumptions!$D$686/100 * x17_channel_gain_after_costs/100)) -> 66.277475 | C27: =(eu_revenue_eur_m * x14_incentive_claims_central/100 * process_leak_pct/100 + eu_revenue_eur_m * x5_targeting_gain_central/100) + sfse_eu_nv_contracts_2025 * upgrade_capture_uplift/100 * margin_per_repeat_sale / 1000000 + (buyback_payables_current_eur_m * MAX(0, x18_exp_twosided_book)/100 + buyback_payables_current_eur_m * (x17_days_cut * x17_day_cost_central/10000 + x17_share_routed/100 * x17_channel_gain_after_costs/100)) -> 205.6438 | D27: =(eu_revenue_eur_m * x14_incentive_claims_high/100 * Assumptions!$E$114/100 + eu_revenue_eur_m * x5_targeting_gain_high/100) + sfse_eu_nv_contracts_2025 * Assumptions!$E$134/100 * Assumptions!$E$135 / 1000000 + (buyback_payables_current_eur_m * MAX(0, x18_exp_twosided_book)/100 + buyback_payables_current_eur_m * (Assumptions!$E$685 * x17_day_cost_high/10000 + Assumptions!$E$686/100 * x17_channel_gain_before_opex/100)) -> 586.58949
A28: Total, one year in ten | B28: =(eu_revenue_eur_m * x14_incentive_claims_low/100 * Assumptions!$D$114/100 + eu_revenue_eur_m * x5_targeting_gain_low/100) + sfse_eu_nv_contracts_2025 * Assumptions!$D$134/100 * Assumptions!$D$135 / 1000000 + ((buyback_payables_current_eur_m * (ABS(level_1y_p10_book)/100 + (curve_1y_p80_known/2/retained_1y_pooled * (1 - Assumptions!$D$117/100) + curve_1y_p80_unknown/2/retained_1y_pooled * Assumptions!$D$117/100))) * x18_joint_share_book/100 + buyback_payables_current_eur_m * (Assumptions!$D$685 * x17_day_cost_low/10000 + Assumptions!$D$686/100 * x17_channel_gain_after_costs/100)) -> 146.35185 | C28: =(eu_revenue_eur_m * x14_incentive_claims_central/100 * process_leak_pct/100 + eu_revenue_eur_m * x5_targeting_gain_central/100) + sfse_eu_nv_contracts_2025 * upgrade_capture_uplift/100 * margin_per_repeat_sale / 1000000 + ((buyback_payables_current_eur_m * (ABS(level_1y_p10_book)/100 + (curve_1y_p80_known/2/retained_1y_pooled * (1 - thin_share_of_book/100) + curve_1y_p80_unknown/2/retained_1y_pooled * thin_share_of_book/100))) * x18_joint_share_book/100 + buyback_payables_current_eur_m * (x17_days_cut * x17_day_cost_central/10000 + x17_share_routed/100 * x17_channel_gain_after_costs/100)) -> 298.11522 | D28: =(eu_revenue_eur_m * x14_incentive_claims_high/100 * Assumptions!$E$114/100 + eu_revenue_eur_m * x5_targeting_gain_high/100) + sfse_eu_nv_contracts_2025 * Assumptions!$E$134/100 * Assumptions!$E$135 / 1000000 + ((buyback_payables_current_eur_m * (ABS(level_1y_p10_book)/100 + (curve_1y_p80_known/2/retained_1y_pooled * (1 - Assumptions!$E$117/100) + curve_1y_p80_unknown/2/retained_1y_pooled * Assumptions!$E$117/100))) * x18_joint_share_book/100 + buyback_payables_current_eur_m * (Assumptions!$E$685 * x17_day_cost_high/10000 + Assumptions!$E$686/100 * x17_channel_gain_before_opex/100)) -> 691.45796
A31: How much of this is evidence?
B32: expected, EUR m | C32: share | D32: one in ten, EUR m | E32: share | F32: meaning
A33: Disclosed exposure, measured shocks (leak 3, the level and the curve) | B33: =buyback_payables_current_eur_m * MAX(0, x18_exp_twosided_book)/100 -> 0 | C33: =B33/((eu_revenue_eur_m * x14_incentive_claims_central/100 * process_leak_pct/100 + eu_revenue_eur_m * x5_targeting_gain_central/100) + sfse_eu_nv_contracts_2025 * upgrade_capture_uplift/100 * margin_per_repeat_sale / 1000000 + (buyback_payables_current_eur_m * MAX(0, x18_exp_twosided_book)/100 + buyback_payables_current_eur_m * (x17_days_cut * x17_day_cost_central/10000 + x17_share_routed/100 * x17_channel_gain_after_costs/100))) -> 0 | D33: =(buyback_payables_current_eur_m * (ABS(level_1y_p10_book)/100 + (curve_1y_p80_known/2/retained_1y_pooled * (1 - thin_share_of_book/100) + curve_1y_p80_unknown/2/retained_1y_pooled * thin_share_of_book/100))) * x18_joint_share_book/100 -> 92.471421 | E33: =D33/((eu_revenue_eur_m * x14_incentive_claims_central/100 * process_leak_pct/100 + eu_revenue_eur_m * x5_targeting_gain_central/100) + sfse_eu_nv_contracts_2025 * upgrade_capture_uplift/100 * margin_per_repeat_sale / 1000000 + ((buyback_payables_current_eur_m * (ABS(level_1y_p10_book)/100 + (curve_1y_p80_known/2/retained_1y_pooled * (1 - thin_share_of_book/100) + curve_1y_p80_unknown/2/retained_1y_pooled * thin_share_of_book/100))) * x18_joint_share_book/100 + buyback_payables_current_eur_m * (x17_days_cut * x17_day_cost_central/10000 + x17_share_routed/100 * x17_channel_gain_after_costs/100))) -> 0.31018685 | F33: our own analysis, on a disclosed exposure: nothing expected, the largest line in a bad year
A34: Measured costs, assumed reach (leak 3, resale execution) | B34: =buyback_payables_current_eur_m * (x17_days_cut * x17_day_cost_central/10000 + x17_share_routed/100 * x17_channel_gain_after_costs/100) -> 24.81171 | C34: =B34/((eu_revenue_eur_m * x14_incentive_claims_central/100 * process_leak_pct/100 + eu_revenue_eur_m * x5_targeting_gain_central/100) + sfse_eu_nv_contracts_2025 * upgrade_capture_uplift/100 * margin_per_repeat_sale / 1000000 + (buyback_payables_current_eur_m * MAX(0, x18_exp_twosided_book)/100 + buyback_payables_current_eur_m * (x17_days_cut * x17_day_cost_central/10000 + x17_share_routed/100 * x17_channel_gain_after_costs/100))) -> 0.12065382 | D34: =buyback_payables_current_eur_m * (x17_days_cut * x17_day_cost_central/10000 + x17_share_routed/100 * x17_channel_gain_after_costs/100) -> 24.81171 | E34: =D34/((eu_revenue_eur_m * x14_incentive_claims_central/100 * process_leak_pct/100 + eu_revenue_eur_m * x5_targeting_gain_central/100) + sfse_eu_nv_contracts_2025 * upgrade_capture_uplift/100 * margin_per_repeat_sale / 1000000 + ((buyback_payables_current_eur_m * (ABS(level_1y_p10_book)/100 + (curve_1y_p80_known/2/retained_1y_pooled * (1 - thin_share_of_book/100) + curve_1y_p80_unknown/2/retained_1y_pooled * thin_share_of_book/100))) * x18_joint_share_book/100 + buyback_payables_current_eur_m * (x17_days_cut * x17_day_cost_central/10000 + x17_share_routed/100 * x17_channel_gain_after_costs/100))) -> 0.083228592 | F34: a day in stock and the retail margin are measured; the days cut and the share routed are assumed
A35: Measured timing, assumed conversion (leak 2) | B35: =sfse_eu_nv_contracts_2025 * upgrade_capture_uplift/100 * margin_per_repeat_sale / 1000000 -> 38.76828 | C35: =B35/((eu_revenue_eur_m * x14_incentive_claims_central/100 * process_leak_pct/100 + eu_revenue_eur_m * x5_targeting_gain_central/100) + sfse_eu_nv_contracts_2025 * upgrade_capture_uplift/100 * margin_per_repeat_sale / 1000000 + (buyback_payables_current_eur_m * MAX(0, x18_exp_twosided_book)/100 + buyback_payables_current_eur_m * (x17_days_cut * x17_day_cost_central/10000 + x17_share_routed/100 * x17_channel_gain_after_costs/100))) -> 0.18852151 | D35: =sfse_eu_nv_contracts_2025 * upgrade_capture_uplift/100 * margin_per_repeat_sale / 1000000 -> 38.76828 | E35: =D35/((eu_revenue_eur_m * x14_incentive_claims_central/100 * process_leak_pct/100 + eu_revenue_eur_m * x5_targeting_gain_central/100) + sfse_eu_nv_contracts_2025 * upgrade_capture_uplift/100 * margin_per_repeat_sale / 1000000 + ((buyback_payables_current_eur_m * (ABS(level_1y_p10_book)/100 + (curve_1y_p80_known/2/retained_1y_pooled * (1 - thin_share_of_book/100) + curve_1y_p80_unknown/2/retained_1y_pooled * thin_share_of_book/100))) * x18_joint_share_book/100 + buyback_payables_current_eur_m * (x17_days_cut * x17_day_cost_central/10000 + x17_share_routed/100 * x17_channel_gain_after_costs/100))) -> 0.13004462 | F35: the window is measured and the contracts disclosed; the euros are not
A36: Disclosed base, assumed leak rate (leak 1, claims) | B36: =eu_revenue_eur_m * x14_incentive_claims_central/100 * process_leak_pct/100 -> 77.99355 | C36: =B36/((eu_revenue_eur_m * x14_incentive_claims_central/100 * process_leak_pct/100 + eu_revenue_eur_m * x5_targeting_gain_central/100) + sfse_eu_nv_contracts_2025 * upgrade_capture_uplift/100 * margin_per_repeat_sale / 1000000 + (buyback_payables_current_eur_m * MAX(0, x18_exp_twosided_book)/100 + buyback_payables_current_eur_m * (x17_days_cut * x17_day_cost_central/10000 + x17_share_routed/100 * x17_channel_gain_after_costs/100))) -> 0.37926527 | D36: =eu_revenue_eur_m * x14_incentive_claims_central/100 * process_leak_pct/100 -> 77.99355 | E36: =D36/((eu_revenue_eur_m * x14_incentive_claims_central/100 * process_leak_pct/100 + eu_revenue_eur_m * x5_targeting_gain_central/100) + sfse_eu_nv_contracts_2025 * upgrade_capture_uplift/100 * margin_per_repeat_sale / 1000000 + ((buyback_payables_current_eur_m * (ABS(level_1y_p10_book)/100 + (curve_1y_p80_known/2/retained_1y_pooled * (1 - thin_share_of_book/100) + curve_1y_p80_unknown/2/retained_1y_pooled * thin_share_of_book/100))) * x18_joint_share_book/100 + buyback_payables_current_eur_m * (x17_days_cut * x17_day_cost_central/10000 + x17_share_routed/100 * x17_channel_gain_after_costs/100))) -> 0.26162217 | F36: the group's own incentive claims (20-F, worldwide); the share paid wrongly is assumed
A37: Derived from published studies (leak 1, targeting) | B37: =eu_revenue_eur_m * x5_targeting_gain_central/100 -> 64.070257 | C37: =B37/((eu_revenue_eur_m * x14_incentive_claims_central/100 * process_leak_pct/100 + eu_revenue_eur_m * x5_targeting_gain_central/100) + sfse_eu_nv_contracts_2025 * upgrade_capture_uplift/100 * margin_per_repeat_sale / 1000000 + (buyback_payables_current_eur_m * MAX(0, x18_exp_twosided_book)/100 + buyback_payables_current_eur_m * (x17_days_cut * x17_day_cost_central/10000 + x17_share_routed/100 * x17_channel_gain_after_costs/100))) -> 0.3115594 | D37: =eu_revenue_eur_m * x5_targeting_gain_central/100 -> 64.070257 | E37: =D37/((eu_revenue_eur_m * x14_incentive_claims_central/100 * process_leak_pct/100 + eu_revenue_eur_m * x5_targeting_gain_central/100) + sfse_eu_nv_contracts_2025 * upgrade_capture_uplift/100 * margin_per_repeat_sale / 1000000 + ((buyback_payables_current_eur_m * (ABS(level_1y_p10_book)/100 + (curve_1y_p80_known/2/retained_1y_pooled * (1 - thin_share_of_book/100) + curve_1y_p80_unknown/2/retained_1y_pooled * thin_share_of_book/100))) * x18_joint_share_book/100 + buyback_payables_current_eur_m * (x17_days_cut * x17_day_cost_central/10000 + x17_share_routed/100 * x17_channel_gain_after_costs/100))) -> 0.21491777 | F37: Swiss price sensitivities by income, a European margin, one assumption
A38: Read the split before either total. What we measured best is a tail: leak 3's level and curve cost about nothing in an average year, because the group's buy-back contracts bring the cars back and a rising market pays for a falling one, and they are the largest measured line in a bad year. The expected column rests mostly on disclosed bases with assumed rates (leak 1's claims, leak 2, resale execution's reach), which a pilot should replace, and on leak 1's targeting line, derived from published studies and tested by the pilot's holdout.
A41: One input at a time
A42: input | B42: tier | C42: one in ten at its low | D42: one in ten at its high | E42: swing | F42: swing, expected a year
A43: Claims paid twice, wrongly or too late, as a share of incentive spend | B43: ASSUMPTION | C43: =(eu_revenue_eur_m * x14_incentive_claims_central/100 * Assumptions!$D$114/100 + eu_revenue_eur_m * x5_targeting_gain_central/100) + sfse_eu_nv_contracts_2025 * upgrade_capture_uplift/100 * margin_per_repeat_sale / 1000000 + ((buyback_payables_current_eur_m * (ABS(level_1y_p10_book)/100 + (curve_1y_p80_known/2/retained_1y_pooled * (1 - thin_share_of_book/100) + curve_1y_p80_unknown/2/retained_1y_pooled * thin_share_of_book/100))) * x18_joint_share_book/100 + buyback_payables_current_eur_m * (x17_days_cut * x17_day_cost_central/10000 + x17_share_routed/100 * x17_channel_gain_after_costs/100)) -> 239.62006 | D43: =(eu_revenue_eur_m * x14_incentive_claims_central/100 * Assumptions!$E$114/100 + eu_revenue_eur_m * x5_targeting_gain_central/100) + sfse_eu_nv_contracts_2025 * upgrade_capture_uplift/100 * margin_per_repeat_sale / 1000000 + ((buyback_payables_current_eur_m * (ABS(level_1y_p10_book)/100 + (curve_1y_p80_known/2/retained_1y_pooled * (1 - thin_share_of_book/100) + curve_1y_p80_unknown/2/retained_1y_pooled * thin_share_of_book/100))) * x18_joint_share_book/100 + buyback_payables_current_eur_m * (x17_days_cut * x17_day_cost_central/10000 + x17_share_routed/100 * x17_channel_gain_after_costs/100)) -> 415.10554 | E43: =ABS(D43-C43) -> 175.48549 | F43: =ABS(((eu_revenue_eur_m * x14_incentive_claims_central/100 * Assumptions!$E$114/100 + eu_revenue_eur_m * x5_targeting_gain_central/100) + sfse_eu_nv_contracts_2025 * upgrade_capture_uplift/100 * margin_per_repeat_sale / 1000000 + (buyback_payables_current_eur_m * MAX(0, x18_exp_twosided_book)/100 + buyback_payables_current_eur_m * (x17_days_cut * x17_day_cost_central/10000 + x17_share_routed/100 * x17_channel_gain_after_costs/100))) - ((eu_revenue_eur_m * x14_incentive_claims_central/100 * Assumptions!$D$114/100 + eu_revenue_eur_m * x5_targeting_gain_central/100) + sfse_eu_nv_contracts_2025 * upgrade_capture_uplift/100 * margin_per_repeat_sale / 1000000 + (buyback_payables_current_eur_m * MAX(0, x18_exp_twosided_book)/100 + buyback_payables_current_eur_m * (x17_days_cut * x17_day_cost_central/10000 + x17_share_routed/100 * x17_channel_gain_after_costs/100)))) -> 175.48549
A44: Extra share of customers retained by contacting them at the right moment | B44: ASSUMPTION | C44: =(eu_revenue_eur_m * x14_incentive_claims_central/100 * process_leak_pct/100 + eu_revenue_eur_m * x5_targeting_gain_central/100) + sfse_eu_nv_contracts_2025 * Assumptions!$D$134/100 * margin_per_repeat_sale / 1000000 + ((buyback_payables_current_eur_m * (ABS(level_1y_p10_book)/100 + (curve_1y_p80_known/2/retained_1y_pooled * (1 - thin_share_of_book/100) + curve_1y_p80_unknown/2/retained_1y_pooled * thin_share_of_book/100))) * x18_joint_share_book/100 + buyback_payables_current_eur_m * (x17_days_cut * x17_day_cost_central/10000 + x17_share_routed/100 * x17_channel_gain_after_costs/100)) -> 272.2697 | D44: =(eu_revenue_eur_m * x14_incentive_claims_central/100 * process_leak_pct/100 + eu_revenue_eur_m * x5_targeting_gain_central/100) + sfse_eu_nv_contracts_2025 * Assumptions!$E$134/100 * margin_per_repeat_sale / 1000000 + ((buyback_payables_current_eur_m * (ABS(level_1y_p10_book)/100 + (curve_1y_p80_known/2/retained_1y_pooled * (1 - thin_share_of_book/100) + curve_1y_p80_unknown/2/retained_1y_pooled * thin_share_of_book/100))) * x18_joint_share_book/100 + buyback_payables_current_eur_m * (x17_days_cut * x17_day_cost_central/10000 + x17_share_routed/100 * x17_channel_gain_after_costs/100)) -> 336.8835 | E44: =ABS(D44-C44) -> 64.6138 | F44: =ABS(((eu_revenue_eur_m * x14_incentive_claims_central/100 * process_leak_pct/100 + eu_revenue_eur_m * x5_targeting_gain_central/100) + sfse_eu_nv_contracts_2025 * Assumptions!$E$134/100 * margin_per_repeat_sale / 1000000 + (buyback_payables_current_eur_m * MAX(0, x18_exp_twosided_book)/100 + buyback_payables_current_eur_m * (x17_days_cut * x17_day_cost_central/10000 + x17_share_routed/100 * x17_channel_gain_after_costs/100))) - ((eu_revenue_eur_m * x14_incentive_claims_central/100 * process_leak_pct/100 + eu_revenue_eur_m * x5_targeting_gain_central/100) + sfse_eu_nv_contracts_2025 * Assumptions!$D$134/100 * margin_per_repeat_sale / 1000000 + (buyback_payables_current_eur_m * MAX(0, x18_exp_twosided_book)/100 + buyback_payables_current_eur_m * (x17_days_cut * x17_day_cost_central/10000 + x17_share_routed/100 * x17_channel_gain_after_costs/100)))) -> 64.6138
A45: Contribution from one retained customer's next car | B45: ASSUMPTION | C45: =(eu_revenue_eur_m * x14_incentive_claims_central/100 * process_leak_pct/100 + eu_revenue_eur_m * x5_targeting_gain_central/100) + sfse_eu_nv_contracts_2025 * upgrade_capture_uplift/100 * Assumptions!$D$135 / 1000000 + ((buyback_payables_current_eur_m * (ABS(level_1y_p10_book)/100 + (curve_1y_p80_known/2/retained_1y_pooled * (1 - thin_share_of_book/100) + curve_1y_p80_unknown/2/retained_1y_pooled * thin_share_of_book/100))) * x18_joint_share_book/100 + buyback_payables_current_eur_m * (x17_days_cut * x17_day_cost_central/10000 + x17_share_routed/100 * x17_channel_gain_after_costs/100)) -> 278.73108 | D45: =(eu_revenue_eur_m * x14_incentive_claims_central/100 * process_leak_pct/100 + eu_revenue_eur_m * x5_targeting_gain_central/100) + sfse_eu_nv_contracts_2025 * upgrade_capture_uplift/100 * Assumptions!$E$135 / 1000000 + ((buyback_payables_current_eur_m * (ABS(level_1y_p10_book)/100 + (curve_1y_p80_known/2/retained_1y_pooled * (1 - thin_share_of_book/100) + curve_1y_p80_unknown/2/retained_1y_pooled * thin_share_of_book/100))) * x18_joint_share_book/100 + buyback_payables_current_eur_m * (x17_days_cut * x17_day_cost_central/10000 + x17_share_routed/100 * x17_channel_gain_after_costs/100)) -> 327.19143 | E45: =ABS(D45-C45) -> 48.46035 | F45: =ABS(((eu_revenue_eur_m * x14_incentive_claims_central/100 * process_leak_pct/100 + eu_revenue_eur_m * x5_targeting_gain_central/100) + sfse_eu_nv_contracts_2025 * upgrade_capture_uplift/100 * Assumptions!$E$135 / 1000000 + (buyback_payables_current_eur_m * MAX(0, x18_exp_twosided_book)/100 + buyback_payables_current_eur_m * (x17_days_cut * x17_day_cost_central/10000 + x17_share_routed/100 * x17_channel_gain_after_costs/100))) - ((eu_revenue_eur_m * x14_incentive_claims_central/100 * process_leak_pct/100 + eu_revenue_eur_m * x5_targeting_gain_central/100) + sfse_eu_nv_contracts_2025 * upgrade_capture_uplift/100 * Assumptions!$D$135 / 1000000 + (buyback_payables_current_eur_m * MAX(0, x18_exp_twosided_book)/100 + buyback_payables_current_eur_m * (x17_days_cut * x17_day_cost_central/10000 + x17_share_routed/100 * x17_channel_gain_after_costs/100)))) -> 48.46035
A46: Share of the buy-back book with little history | B46: ASSUMPTION | C46: =(eu_revenue_eur_m * x14_incentive_claims_central/100 * process_leak_pct/100 + eu_revenue_eur_m * x5_targeting_gain_central/100) + sfse_eu_nv_contracts_2025 * upgrade_capture_uplift/100 * margin_per_repeat_sale / 1000000 + ((buyback_payables_current_eur_m * (ABS(level_1y_p10_book)/100 + (curve_1y_p80_known/2/retained_1y_pooled * (1 - Assumptions!$D$117/100) + curve_1y_p80_unknown/2/retained_1y_pooled * Assumptions!$D$117/100))) * x18_joint_share_book/100 + buyback_payables_current_eur_m * (x17_days_cut * x17_day_cost_central/10000 + x17_share_routed/100 * x17_channel_gain_after_costs/100)) -> 285.71817 | D46: =(eu_revenue_eur_m * x14_incentive_claims_central/100 * process_leak_pct/100 + eu_revenue_eur_m * x5_targeting_gain_central/100) + sfse_eu_nv_contracts_2025 * upgrade_capture_uplift/100 * margin_per_repeat_sale / 1000000 + ((buyback_payables_current_eur_m * (ABS(level_1y_p10_book)/100 + (curve_1y_p80_known/2/retained_1y_pooled * (1 - Assumptions!$E$117/100) + curve_1y_p80_unknown/2/retained_1y_pooled * Assumptions!$E$117/100))) * x18_joint_share_book/100 + buyback_payables_current_eur_m * (x17_days_cut * x17_day_cost_central/10000 + x17_share_routed/100 * x17_channel_gain_after_costs/100)) -> 310.51227 | E46: =ABS(D46-C46) -> 24.794098 | F46: =ABS(((eu_revenue_eur_m * x14_incentive_claims_central/100 * process_leak_pct/100 + eu_revenue_eur_m * x5_targeting_gain_central/100) + sfse_eu_nv_contracts_2025 * upgrade_capture_uplift/100 * margin_per_repeat_sale / 1000000 + (buyback_payables_current_eur_m * MAX(0, x18_exp_twosided_book)/100 + buyback_payables_current_eur_m * (x17_days_cut * x17_day_cost_central/10000 + x17_share_routed/100 * x17_channel_gain_after_costs/100))) - ((eu_revenue_eur_m * x14_incentive_claims_central/100 * process_leak_pct/100 + eu_revenue_eur_m * x5_targeting_gain_central/100) + sfse_eu_nv_contracts_2025 * upgrade_capture_uplift/100 * margin_per_repeat_sale / 1000000 + (buyback_payables_current_eur_m * MAX(0, x18_exp_twosided_book)/100 + buyback_payables_current_eur_m * (x17_days_cut * x17_day_cost_central/10000 + x17_share_routed/100 * x17_channel_gain_after_costs/100)))) -> 0
A47: Days cut from the average time to sale of a year's buy-back returns | B47: ASSUMPTION | C47: =(eu_revenue_eur_m * x14_incentive_claims_central/100 * process_leak_pct/100 + eu_revenue_eur_m * x5_targeting_gain_central/100) + sfse_eu_nv_contracts_2025 * upgrade_capture_uplift/100 * margin_per_repeat_sale / 1000000 + ((buyback_payables_current_eur_m * (ABS(level_1y_p10_book)/100 + (curve_1y_p80_known/2/retained_1y_pooled * (1 - thin_share_of_book/100) + curve_1y_p80_unknown/2/retained_1y_pooled * thin_share_of_book/100))) * x18_joint_share_book/100 + buyback_payables_current_eur_m * (Assumptions!$D$685 * x17_day_cost_central/10000 + x17_share_routed/100 * x17_channel_gain_after_costs/100)) -> 289.95976 | D47: =(eu_revenue_eur_m * x14_incentive_claims_central/100 * process_leak_pct/100 + eu_revenue_eur_m * x5_targeting_gain_central/100) + sfse_eu_nv_contracts_2025 * upgrade_capture_uplift/100 * margin_per_repeat_sale / 1000000 + ((buyback_payables_current_eur_m * (ABS(level_1y_p10_book)/100 + (curve_1y_p80_known/2/retained_1y_pooled * (1 - thin_share_of_book/100) + curve_1y_p80_unknown/2/retained_1y_pooled * thin_share_of_book/100))) * x18_joint_share_book/100 + buyback_payables_current_eur_m * (Assumptions!$E$685 * x17_day_cost_central/10000 + x17_share_routed/100 * x17_channel_gain_after_costs/100)) -> 314.42613 | E47: =ABS(D47-C47) -> 24.466365 | F47: =ABS(((eu_revenue_eur_m * x14_incentive_claims_central/100 * process_leak_pct/100 + eu_revenue_eur_m * x5_targeting_gain_central/100) + sfse_eu_nv_contracts_2025 * upgrade_capture_uplift/100 * margin_per_repeat_sale / 1000000 + (buyback_payables_current_eur_m * MAX(0, x18_exp_twosided_book)/100 + buyback_payables_current_eur_m * (Assumptions!$E$685 * x17_day_cost_central/10000 + x17_share_routed/100 * x17_channel_gain_after_costs/100))) - ((eu_revenue_eur_m * x14_incentive_claims_central/100 * process_leak_pct/100 + eu_revenue_eur_m * x5_targeting_gain_central/100) + sfse_eu_nv_contracts_2025 * upgrade_capture_uplift/100 * margin_per_repeat_sale / 1000000 + (buyback_payables_current_eur_m * MAX(0, x18_exp_twosided_book)/100 + buyback_payables_current_eur_m * (Assumptions!$D$685 * x17_day_cost_central/10000 + x17_share_routed/100 * x17_channel_gain_after_costs/100)))) -> 24.466365
A48: Share of a year's buy-back returns routed to the group's own retail instead of the trade | B48: ASSUMPTION | C48: =(eu_revenue_eur_m * x14_incentive_claims_central/100 * process_leak_pct/100 + eu_revenue_eur_m * x5_targeting_gain_central/100) + sfse_eu_nv_contracts_2025 * upgrade_capture_uplift/100 * margin_per_repeat_sale / 1000000 + ((buyback_payables_current_eur_m * (ABS(level_1y_p10_book)/100 + (curve_1y_p80_known/2/retained_1y_pooled * (1 - thin_share_of_book/100) + curve_1y_p80_unknown/2/retained_1y_pooled * thin_share_of_book/100))) * x18_joint_share_book/100 + buyback_payables_current_eur_m * (x17_days_cut * x17_day_cost_central/10000 + Assumptions!$D$686/100 * x17_channel_gain_after_costs/100)) -> 293.01474 | D48: =(eu_revenue_eur_m * x14_incentive_claims_central/100 * process_leak_pct/100 + eu_revenue_eur_m * x5_targeting_gain_central/100) + sfse_eu_nv_contracts_2025 * upgrade_capture_uplift/100 * margin_per_repeat_sale / 1000000 + ((buyback_payables_current_eur_m * (ABS(level_1y_p10_book)/100 + (curve_1y_p80_known/2/retained_1y_pooled * (1 - thin_share_of_book/100) + curve_1y_p80_unknown/2/retained_1y_pooled * thin_share_of_book/100))) * x18_joint_share_book/100 + buyback_payables_current_eur_m * (x17_days_cut * x17_day_cost_central/10000 + Assumptions!$E$686/100 * x17_channel_gain_after_costs/100)) -> 306.61602 | E48: =ABS(D48-C48) -> 13.60128 | F48: =ABS(((eu_revenue_eur_m * x14_incentive_claims_central/100 * process_leak_pct/100 + eu_revenue_eur_m * x5_targeting_gain_central/100) + sfse_eu_nv_contracts_2025 * upgrade_capture_uplift/100 * margin_per_repeat_sale / 1000000 + (buyback_payables_current_eur_m * MAX(0, x18_exp_twosided_book)/100 + buyback_payables_current_eur_m * (x17_days_cut * x17_day_cost_central/10000 + Assumptions!$E$686/100 * x17_channel_gain_after_costs/100))) - ((eu_revenue_eur_m * x14_incentive_claims_central/100 * process_leak_pct/100 + eu_revenue_eur_m * x5_targeting_gain_central/100) + sfse_eu_nv_contracts_2025 * upgrade_capture_uplift/100 * margin_per_repeat_sale / 1000000 + (buyback_payables_current_eur_m * MAX(0, x18_exp_twosided_book)/100 + buyback_payables_current_eur_m * (x17_days_cut * x17_day_cost_central/10000 + Assumptions!$D$686/100 * x17_channel_gain_after_costs/100)))) -> 13.60128
...

Sheet Leak 1 - Incentives
A1: Leak 1: the spend nobody can see
A3: The claims line takes the group's own claims-based incentive spend: the sales-incentive provision in its 20-F (Note 21), worldwide, as a share of net revenue (analysis/incentive_anchor_report.md). No regional total is disclosed, and the share of claims paid wrongly is an assumption. The targeting line is derived from published studies and one assumption (analysis/optimal_incentive_report.md). Neither is a measurement of the group in Europe: that is the reason the ledger has to be built.
A5: EUR millions a year, Enlarged Europe
A6: Incentive claims (the group's own share of revenue, applied to Europe) | B6: =eu_revenue_eur_m * x14_incentive_claims_central/100 -> 3899.6775 | C6: eu_revenue_eur_m x x14_incentive_claims_central (20-F Note 21, worldwide)
A7: Claims paid twice, wrongly or too late | B7: =eu_revenue_eur_m * x14_incentive_claims_central/100 * process_leak_pct/100 -> 77.99355 | C7: process_leak_pct
A8: Profit lost by giving every buyer the same incentive | B8: =eu_revenue_eur_m * x5_targeting_gain_central/100 -> 64.070257 | C8: x5_targeting_gain_central: what giving each income quartile its own incentive earns, derived in X5
A9: Value at risk, leak 1 | B9: =(eu_revenue_eur_m * x14_incentive_claims_central/100 * process_leak_pct/100 + eu_revenue_eur_m * x5_targeting_gain_central/100) -> 142.06381
A11: Of which a controls layer actually recovers | B11: =eu_revenue_eur_m * x14_incentive_claims_central/100 * process_leak_pct/100 * recoverable_share/100 -> 23.398065 | C11: leakage that exists is not leakage you can recover
A13: Not sized here, on purpose
A14: Spend above the best uniform level. The targeting line takes today's uniform incentive as the best uniform one, so it cannot say whether the group spends too much on average. Public data cannot either: the published margins and price sensitivities disagree. Only a randomised holdout on the incentive's level measures it.
A15: Pass-through leakage - money meant for the buyer that the dealer keeps - is real and measured in the literature (buyers receive 70-90% of a customer rebate but only 30-40% of a dealer discount, Busse et al. 2006, US data). It is not converted into euros here because that would need a second assumption about how the group's spend splits between the two kinds of programme. The ledger measures it per programme instead of assuming it.

Sheet Leak 2 - Upgrade timing
A1: Leak 2: the moment nobody catches
A3: The upgrade moment is when the car is worth more than the balance still owed on it. Both sides are held as a share of the list price, so no currency or exchange rate enters. The value curve is the measured UK retained-value curve from the 2018 adverts, before the shortage; the balance is a straight amortising contract.
A5: Measured value curve (share of list price)
A6: years | B6: 0 | C6: 1 | D6: 2 | E6: 3 | F6: 4 | G6: 5
